Traceback (most recent call last):
  File "/Users/jd74192/opt/anaconda3/lib/python3.9/site-packages/jupyter_cache/executors/utils.py", line 51, in single_nb_execution
    executenb(
  File "/Users/jd74192/opt/anaconda3/lib/python3.9/site-packages/nbclient/client.py", line 1204, in execute
    return NotebookClient(nb=nb, resources=resources, km=km, **kwargs).execute()
  File "/Users/jd74192/opt/anaconda3/lib/python3.9/site-packages/nbclient/util.py", line 84, in wrapped
    return just_run(coro(*args, **kwargs))
  File "/Users/jd74192/opt/anaconda3/lib/python3.9/site-packages/nbclient/util.py", line 62, in just_run
    return loop.run_until_complete(coro)
  File "/Users/jd74192/opt/anaconda3/lib/python3.9/asyncio/base_events.py", line 647, in run_until_complete
    return future.result()
  File "/Users/jd74192/opt/anaconda3/lib/python3.9/site-packages/nbclient/client.py", line 663, in async_execute
    await self.async_execute_cell(
  File "/Users/jd74192/opt/anaconda3/lib/python3.9/site-packages/nbclient/client.py", line 965, in async_execute_cell
    await self._check_raise_for_error(cell, cell_index, exec_reply)
  File "/Users/jd74192/opt/anaconda3/lib/python3.9/site-packages/nbclient/client.py", line 862, in _check_raise_for_error
    raise CellExecutionError.from_cell_and_msg(cell, exec_reply_content)
nbclient.exceptions.CellExecutionError: An error occurred while executing the following cell:
------------------
df_campaigns_18['Transaction_Time'] = pd.to_datetime(df_campaigns_18['transaction_timestamp']).dt.time
df_campaigns_18['Transaction_Date'] = pd.to_datetime(df_campaigns_18['transaction_timestamp']).dt.date
cam18_age = df_campaigns_18.groupby(['age','Transaction_Date'],as_index=False).agg({'sales_value':'sum'})

df_campaigns_13['Transaction_Time'] = pd.to_datetime(df_campaigns_13['transaction_timestamp']).dt.time
df_campaigns_13['Transaction_Date'] = pd.to_datetime(df_campaigns_13['transaction_timestamp']).dt.date
cam13_age = df_campaigns_13.groupby(['age','Transaction_Date'],as_index=False).agg({'sales_value':'sum'})

df_campaigns_8['Transaction_Time'] = pd.to_datetime(df_campaigns_8['transaction_timestamp']).dt.time
df_campaigns_8['Transaction_Date'] = pd.to_datetime(df_campaigns_8['transaction_timestamp']).dt.date
cam8_age = df_campaigns_8.groupby(['age','Transaction_Date'],as_index=False).agg({'sales_value':'sum'})
------------------

[0;31m---------------------------------------------------------------------------[0m
[0;31mNameError[0m                                 Traceback (most recent call last)
[0;32m/var/folders/m_/qj_5t76n7nd04vpk93_tlblr0000gp/T/ipykernel_10924/4078123064.py[0m in [0;36m<module>[0;34m[0m
[0;32m----> 1[0;31m [0mdf_campaigns_18[0m[0;34m[[0m[0;34m'Transaction_Time'[0m[0;34m][0m [0;34m=[0m [0mpd[0m[0;34m.[0m[0mto_datetime[0m[0;34m([0m[0mdf_campaigns_18[0m[0;34m[[0m[0;34m'transaction_timestamp'[0m[0;34m][0m[0;34m)[0m[0;34m.[0m[0mdt[0m[0;34m.[0m[0mtime[0m[0;34m[0m[0;34m[0m[0m
[0m[1;32m      2[0m [0mdf_campaigns_18[0m[0;34m[[0m[0;34m'Transaction_Date'[0m[0;34m][0m [0;34m=[0m [0mpd[0m[0;34m.[0m[0mto_datetime[0m[0;34m([0m[0mdf_campaigns_18[0m[0;34m[[0m[0;34m'transaction_timestamp'[0m[0;34m][0m[0;34m)[0m[0;34m.[0m[0mdt[0m[0;34m.[0m[0mdate[0m[0;34m[0m[0;34m[0m[0m
[1;32m      3[0m [0mcam18_age[0m [0;34m=[0m [0mdf_campaigns_18[0m[0;34m.[0m[0mgroupby[0m[0;34m([0m[0;34m[[0m[0;34m'age'[0m[0;34m,[0m[0;34m'Transaction_Date'[0m[0;34m][0m[0;34m,[0m[0mas_index[0m[0;34m=[0m[0;32mFalse[0m[0;34m)[0m[0;34m.[0m[0magg[0m[0;34m([0m[0;34m{[0m[0;34m'sales_value'[0m[0;34m:[0m[0;34m'sum'[0m[0;34m}[0m[0;34m)[0m[0;34m[0m[0;34m[0m[0m
[1;32m      4[0m [0;34m[0m[0m
[1;32m      5[0m [0mdf_campaigns_13[0m[0;34m[[0m[0;34m'Transaction_Time'[0m[0;34m][0m [0;34m=[0m [0mpd[0m[0;34m.[0m[0mto_datetime[0m[0;34m([0m[0mdf_campaigns_13[0m[0;34m[[0m[0;34m'transaction_timestamp'[0m[0;34m][0m[0;34m)[0m[0;34m.[0m[0mdt[0m[0;34m.[0m[0mtime[0m[0;34m[0m[0;34m[0m[0m

[0;31mNameError[0m: name 'df_campaigns_18' is not defined
NameError: name 'df_campaigns_18' is not defined

